[TOC]

# 错误和异常

## 错误Error

逻辑错误或语法错误

比如算法写错了，变量名不符合要求写错了等等，错误是可以避免的。

## 异常Exception

意外情况,有个前提就是没有上面说的错误,也就是说程序写的没问题,但在某些情况下，会出现一些意外导致程序无法执行下去。

例如打开或创建一个文件,这个文件可能不存在/或已存在，又或者网络传输,可能会遇到网络中断等等，这些就是异常，是个意外的情况。异常不可能避免。

在高级变成语言中，一般都有错误和异常的概念，异常可以捕获并处理，但错误不能。

 

```
with open('test') as f:
    pass
# FileNotFoundError: [Errno 2] No such file or directory: 'test'

def 0A():
    pass
# SyntaxError: invalid syntax
```

异常就是程序运行时发生错误的信号,在python中,错误触发的异常如下:

![img](%E5%BC%82%E5%B8%B8%E5%A4%84%E7%90%86.assets/199b3997-d4f4-4d8b-8d54-988b7484060c.jpg)

## 异常产生

主动抛出异常

raise语句显示的抛出异常

Python解释器自己检测到异常

程序会在异常抛出的位置中断执行，如果不捕获就会提前结束程序。

### raise语句

raise后什么都没有，表示抛出最近一个被激活的异常，如果没有被激活的异常，则抛出类型异常(很少用)。

raise后要求应该是BaseException类的子类或实例,如果是类，将被无参实例化。

## 异常捕获

python解释器检测到错误，触发异常（也允许程序员自己触发异常）.

程序员编写特定的代码,专门用来捕捉这个异常（这段代码与程序逻辑无关，与异常处理有关）,如果捕捉成功则进入另外一个处理分支，执行你为其定制的逻辑，使程序不会崩溃，这就是异常处理.

 

```
try:
    待捕获异常代码块
except [异常类型]:
    异常处理代码块
```

except 捕获后面所写的异常类型，可以捕获多个类型的异常；

except如果不写捕获的异常类型，则捕获所有的异常；

 

```
class MyException(Exception):
    pass

try:
    a = 1/0
    raise MyException()
    open('a1.txt')
except MyException:
    print('catch the MyException')

except ZeroDivisionError:
    print("1/0")

except Exception:
    print('Exception')
```

捕获规则：

捕获是从上到下依次比较，如果匹配，则执行匹配的except语句块，如果被一个except语句捕获，其他except语句就不会再次捕获了，如果没有任何一个except语句捕获到这个异常，则该异常向外抛出。

捕获原则：

从大到小，从具体到宽泛。

### as子句

被抛出的异常，应该是异常的实例，as子句可获得这个实例对象。

 

```
class MyException(Exception):
    def __init__(self, code, message):
        self.code = code
        self.message = message

try:
    raise MyException()
    # raise MyException(200, 'ok')
except MyException as e:
    print('MyException = {} {}'.format(e.code, e.message))
except Exception as e:
    print('Exception = {}'.format(e))
```

### finally子句

最终，即最后一定要执行的,try...finally语句块中，不管是否发生了异常,都要执行finally的部分。

 

```
f = None
try:
    f = open('text.txt')
except FileNotFoundError as e:
    print('{} {} {}'.format(e.__class__, e.errno, e.strerror))
finally:
    print("清理工作")
    if f:
        f.close()
```

finally中一般放置资源的清理/释放等工作的语句，也可以再次捕捉异常。

### finally执行时机

 

```
# test1
def foo():
    try:
        return 3
    finally:
        print('finally')
    print('===')
print(foo())

# test2
def foo():
    try:
        return 3
    finally:
        return 5
    print('===')
print(foo())
```

测试1进入try,执行return 3，虽然函数有返回值，但是finally一定还要执行，所以打印了finally后，函数返回值。

测试2进入try，执行return 3，虽然函数有返回值，但是finally一定还要执行，所以执行return 5，函数返回。5被压在栈顶，所以返回5。

简单说，函数的返回值取决于最后一个执行的return语句，而finally则是try..finally中最后执行的语句块。

总结

只要语句在try语句块中，那么finally一定会执行，反之，如果再try语句之外，那就不一定了。

### else子句

 

```
try:
    ret = 1 * 0
    # ret = 1 / 0
except ArithmeticError as e:
    print(e)
else:
    print('OK')
finally:
    print('fin')
```

没有任何异常发生，则执行else子句。

## 异常的传递

 

```
def foo1():
    return 1/0

def foo2():
    print('foo2 start')
    foo1()
    print('foo2 stop')  # 会打印吗

foo2()
```

foo2调用了foo1，foo1产生的异常，传递到了foo2中。

异常总是向外层抛出，如果外层没有处理这个异常，就会继续向外抛出；

如果内层捕获并处理了异常，外部就不能捕获到了，如果到了最外层还是没有被处理，就会中断异常所在的线程的执行。

 

```
try:
    try:
        ret = 1/0
    except KeyError as e:  # 未能捕获
        print(e)
    else:
        print('inner OK')
    finally:
        print('inner fin')
except:  # 捕获到内层异常
    print('outer catch')
finally:
    print('outer fin')
```

内部捕获不到异常，会向外层传递异常，但如果内层有finally且其中有return、break语句，则异常会被压制不会向外抛出。

 

```
def foo():
    try:
        ret = 1/0
    except KeyError as e:
        print(e)
    finally:
        print('inner fin')
        return  # 存在，则压制异常

try:
    foo()
except:
    print('outer catch')
finally:
    print('outer fin')
"""
inner fin
outer fin
"""
```

## 异常的捕获时机

1 立即捕获

需要立即返回一个明确的结果

 

```
def parse_int(s):
    try:
        ret = int(s)
    except:
        return 0
    return ret

print(parse_int('a'))
```

2 边界捕获

封装产生了边界

例如，写了一个模块，用户调用这个模块的时候捕获异常，模块内部不需要捕获、处理异常，一旦内部处理了，外部的调用者就无法感知了。

例如open函数，出现的异常交给调用者处理，文件存在就不用再创建了，看是否修改还是删除；再例如自己写了一个类，使用了open函数，但是出现了异常不知道如何处理，就继续向外层抛出，一般来说最外层也就是边界，必须处理这个异常，否则整个线程退出。

# 异常类和继承层次

## BaseException

所有内建异常类的基类

SystemExit

sys.exit()函数引发的异常，异常不捕获处理，就直接交给Python解释器，解释器退出。

 

```
import sys

# print('before')
# sys.exit(1)
# print('SysExit')
# print('outer')

try:
    sys.exit(1)
except SystemExit:
    print('SysExit')
print('Outer')
```

KeyboardInterrupt

对应的捕获用户中断行为Ctrl + C

 

```
try:
    import time
    while True:
        time.sleep(0.5)
        pass
except KeyboardInterrupt:
    print('Ctrl + C')
print('Outer')
```

## Exception及子类

Exception是所有内建的、非系统退出的异常的基类，自定义异常应该继承自它。

### SyntaxError

语法错误，Python将这种错误也归到异常类下面的Exception下的子类，但是这种错误是不可捕获的。

### ArithmeticError

所有算数计算引发的异常，其子类有除零异常等。

### LookupError

使用映射的键或序列的索引无效时引发的异常的基类: IndexError, KeyError

### 自定义异常

从Exception继承的类

 

```
class MyException(Exception):
    pass

try:
    raise MyException()
except MyException:
    print('catch the exception')
```

### 未实现和未实现异常

NotImplemented是个值，单值，是NotImplementedType类的实例。

NotlmplementedError是类型，是异常，返回type

 

```
print(type(NotImplemented))
print(type(NotImplementedError))

# raise NotImplemented
raise NotImplementedError
```

**异常处理**

## if判断

 

```
def test():
    print('test running')
choice_dic={
    '1':test
}
while True:
    choice=input('>>: ').strip()
    if not choice or choice not in choice_dic:continue #这便是一种异常处理机制
    choice_dic[choice]()
```

## try..except..

 

```
try:
    被检测的代码块
except 异常类型:
    try中一旦检测到指定的异常类型,则执行此位置的逻辑代码
```

需要注意的是:异常类只能用来处理指定的异常情况,如果非指定异常则无法处理.

 

```
s1 = 'hello'
try:
    int(s1)
except IndexError as e:
    print(e)

"""
Traceback (most recent call last):
    File "J:/Python_Project/day09/练习/123.py", line 77, in <module>
    int(s1)
ValueError: invalid literal for int() with base 10: 'hello'
"""
```

## 万能异常Exception

可以捕获任意的异常

 

```
s1 = 'hello'
try:
    int(s1)
except Exception as e:
    print(e)
"""
invalid literal for int() with base 10: 'hello'
"""
```

## 多分支处理

虽然万能异常好用,但是也要分情况,如果要对不同的异常定制不同的处理方式,就需要用到多分支了.

 

```
s1 = 'hello'
try:
    int(s1)
except IndexError as e:
    print(e)
except KeyError as e:
    print(e)
except ValueError as e:
    print(e)
except Exception as e:  # 可以在最后,来一个万能异常
    print(e)
```

## 其他形式处理

 

```
s1 = 'hello'
try:
    int(s1)
except IndexError as e:
    print(e)
except KeyError as e:
    print(e)
except ValueError as e:
    print(e)
#except Exception as e:
#    print(e)
else:
    print('try内代码块没有异常则执行我')
finally:
    print('无论异常与否,都会执行该模块,通常是进行清理工作')
```

## 主动出发异常

 

```
try:
    raise TypeError('类型错误')
except Exception as e:
    print(e)
"""
类型错误
"""
```

## 自定义异常

 

```
class EgonException(BaseException):
    def __init__(self,msg):
        self.msg=msg
    def __str__(self):
        return self.msg

try:
    raise EgonException('类型错误')
except EgonException as e:
    print(e)
```

# **总结**

try:

  <语句>  # 捕获可能出现异常的语句代码

except <异常类>:

  <语句>  # 对捕获到的异常进行处理

except <异常类> as <变量名>:

  <语句>  # 捕获某种类型的异常并赋值给一个变量

else:

  <语句>  # 如果没有异常发生,执行此句

finally:

  <语句>  # 退出try时总会执行

try..except的方式比较if的方式的好处:

if本身就可以来处理异常，只不过if的方式，对于不同代码段的同一种异常，需要重复写多分支的if，而这段多分支if与真正的工作无关，写多了你的程序可读性就会及其的差。

try..except的方式，只是python提供给你一种特定的语法结构去做这件事，对于不同代码的同一种异常，python为你定制了一中类型，一个expect就可以捕捉到

try..except这种异常处理机制就是取代if那种方式，让你的程序在不牺牲可读性的前提下增强健壮性和容错性,

异常处理中为每一个异常定制了异常类型（python中统一了类与类型，类型即类），对于同一种异常，一个except就可以捕捉到，可以同时处理多段代码的异常（无需‘写多个if判断式’）减少了代码，增强了可读性

 

```
#_*_coding:utf-8_*_

#if方式处理异常
# num1=input('>>: ') #输入一个字符串试试
# if num1.isdigit():
#     int(num1) #我们的正统程序放到了这里,其余的都属于异常处理范畴
# elif num1.isspace():
#     print('输入的是空格,就执行我这里的逻辑')
# elif len(num1) == 0:
#     print('输入的是空,就执行我这里的逻辑')
# else:
#     print('其他情情况,执行我这里的逻辑')

#第二段代码
# num2=input('>>: ') #输入一个字符串试试
# int(num2)

#第三段代码
# num3=input('>>: ') #输入一个字符串试试
# int(num3)

#try..except..方式处理
try:
    #第一段代码
    num1=input('>>: ') #输入一个字符串试试
    int(num1) #我们的正统程序放到了这里,其余的都属于异常处理范畴
    #第二段代码
    num2=input('>>: ') #输入一个字符串试试
    int(num2)
    #第三段代码
    num3=input('>>: ') #输入一个字符串试试
    int(num3)
except ValueError as e:
    print(e)
```

使用try..except的方式

1：把错误处理和真正的工作分开来

2：代码更易组织，更清晰，复杂的工作任务更容易实现；

3：毫无疑问，更安全了，不至于由于一些小的疏忽而使程序意外崩溃了；

# try工作原理

1 如果try中语句执行时发生异常，搜索except子句，并执行第一个匹配该异常类型的except子句；

2 如果try中语句执行时发生异常，却没有except匹配的异常类型，异常将被递交到外层的try，如果外层不处理将继续向外传递，直至传递到最外层，如果还没有处理，就终止异常所在线程；

3 如果在try执行时没有发生异常，将执行else子句中的语句；

4 无论try中是否发生异常，finally子句最终都会执行。